Workbook

Sheet Pivot tables
D4: Average of Total bill | E4: Column Labels
D5: Row Labels | E5: East | F5: North | G5: South | H5: West | I5: (blank) | J5: Grand Total
D6: Adult | E6: 64370.455 | F6: 57337.037 | G6: 52315.094 | H6: 58268.75 | J6: 56427.66
D7: Senior | E7: 53647.368 | F7: 57494.505 | G7: 46991.852 | H7: 71026.761 | J7: 55583.898
D8: super senior | E8: 76550 | F8: 46951.064 | G8: 33068.519 | H8: 54383.333 | J8: 50009.948
D9: Young adult | E9: 26780 | F9: 25583.333 | G9: 54000 | H9: 128166.67 | J9: 58325
D10: (blank)
D11: Grand Total | E11: 61180.882 | F11: 54700.794 | G11: 47541.873 | H11: 62654.618 | J11: 54963.9
A13: Row Labels | B13: Count of Patient Id | C13: Average of Income (LPA)
A14: 22 | B14: 2 | C14: 10.5 | E14: Row Labels | F14: Avg insurance amount
A15: 28 | B15: 22 | C15: 14.318182 | E15: Adult | F15: 39392.801
A16: 30 | B16: 8 | C16: 9.4375 | E16: Senior | F16: 35437.446
A17: 32 | B17: 24 | C17: 20.5625 | E17: super senior | F17: 36825.167
A18: 33 | B18: 89 | C18: 37.678161 | E18: Young adult | F18: 44424.977
A19: 34 | B19: 9 | C19: 24.222222 | E19: Grand Total | F19: 37718.441
A20: 38 | B20: 133 | C20: 27.073077
A21: 41 | B21: 44 | C21: 23.77381
A22: 42 | B22: 79 | C22: 24.616883
A23: 45 | B23: 45 | C23: 12.931818 | F23: Count of Patient Id | G23: Column Labels
A24: 46 | B24: 3 | C24: 15.666667 | F24: Row Labels | G24: High Priority | H24: Grand Total
A25: 48 | B25: 131 | C25: 18.90625 | F25: East | G25: 0.13989637 | H25: 0.13989637
A26: 50 | B26: 7 | C26: 12.666667 | F26: North | G26: 0.38341969 | H26: 0.38341969
A27: 53 | B27: 99 | C27: 22.035354 | F27: South | G27: 0.30051813 | H27: 0.30051813
A28: 54 | B28: 13 | C28: 13.115385 | F28: West | G28: 0.1761658 | H28: 0.1761658
A29: 58 | B29: 100 | C29: 26.617347 | F29: Grand Total | G29: 1 | H29: 1
A30: 60 | B30: 1 | C30: 400
A31: 62 | B31: 79 | C31: 33.018987
A32: 68 | B32: 63 | C32: 24.880952
A33: 73 | B33: 38 | C33: 29.763158
A34: 82 | B34: 5 | C34: 21.4
A35: 88 | B35: 6 | C35: 16.083333
A36: Grand Total | B36: 1000 | C36: 25.200711
B39: Row Labels | C39: Average of Patient_weight
B40: East | C40: 76.761029
B41: North | C41: 78.723016
B42: South | C42: 77.89697
B43: West | C43: 76.856225
B44: Grand Total | C44: 77.6915
A49: Count of Patient_id | B49: Column Labels
A50: Row Labels | B50: A- | C50: A+ | D50: AB- | E50: AB+ | F50: B- | G50: B+ | H50: O- | I50: O+ | J50: Grand Total
...

Sheet Interactive dashboard
A1: PID0032
E3: financial status
D4: income | E4: total bill | F4: insurance | G4: gender
D5: =_xlfn.XLOOKUP(A1,'Patient Demographics'!A:A,'Patient Demographics'!K:K,FALSE) -> 9 | E5: =_xlfn.XLOOKUP(A1,'Patient Demographics'!A:A,'Billing Details'!J:J,FALSE) -> 45000 | G5: =INDEX('Patient Demographics'!E:E,MATCH('Interactive dashboard'!A1,'Patient Demographics'!A:A)) -> Female
E8: Health indicator
D9: cholesterol level | E9: smoking status | F9: Drinking status | G9: DM | H9: blood Group
D10: =INDEX('Patient Health Records'!U:U,MATCH(A1,'Patient Demographics'!A:A)) -> 196 | E10: =INDEX('Patient Health Records'!X:X,MATCH('Interactive dashboard'!A1,'Patient Demographics'!A:A)) -> FALSE | H10: =INDEX('Patient Health Records'!B:B,MATCH('Interactive dashboard'!A1,'Patient Demographics'!A:A)) -> A-
E11: Outcome
D12: Outcome | E12: Satisfaction

Sheet Patient Education
A1: Patient Id | B1: Education Level | C1: Occupation | D1: Company Type
A2: PID0001 | B2: Master's Degree | C2: Manager | D2: Startup | F2: PID0001
A3: PID0002 | B3: Bachelor's Degree | C3: Teacher | D3: Startup | H3: financial status
A4: PID0003 | B4: School | C4: Clerical Staff | D4: Public | G4: income | H4: total bill | I4: gender
A5: PID0004 | B5: School | C5: Retail Worker | D5: Public | G5: =_xlfn.XLOOKUP(F2,'Patient Demographics'!A:A,'Patient Demographics'!K:K,FALSE) -> 20 | H5: =_xlfn.XLOOKUP(F2,'Billing Details'!A:A,'Billing Details'!J:J,FALSE) -> 60000 | I5: =_xlfn.XLOOKUP(F2,'Patient Demographics'!A:A,'Patient Demographics'!E:E,FALSE) -> Female
A6: PID0005 | B6: Post-graduate | C6: Professor | D6: Startup | H6: Health status
A7: PID0006 | B7: PhD | C7: Scientist | D7: Private | G7: cholesterol | H7: smoking status | I7: drinking status | J7: DM | K7: blood Group
A8: PID0007 | B8: Uneducated | C8: Unemployed | D8: None
A9: PID0008 | B9: Uneducated | C9: Labourer | D9: None
A10: PID0009 | B10: School | C10: Driver | D10: Public
A11: PID0010 | B11: Master's Degree | C11: Doctor | D11: Startup
A12: PID0011 | B12: Master's Degree | C12: Doctor | D12: Public
A13: PID0012 | B13: Bachelor's Degree | C13: Engineer | D13: Public | G13: Tamil Nadu | H13: =VLOOKUP(G13,Facts!A3:B10,2,FALSE) -> South
A14: PID0013 | B14: Bachelor's Degree | C14: Junior Executive | D14: Startup | G14: Maharashtra | H14: =VLOOKUP(G14,Facts!A4:B11,2,FALSE) -> West
A15: PID0014 | B15: Bachelor's Degree | C15: Engineer | D15: Private
A16: PID0015 | B16: School | C16: Retail Worker | D16: Public
A17: PID0016 | B17: Bachelor's Degree | C17: Nurse | D17: Startup
A18: PID0017 | B18: Master's Degree | C18: Manager | D18: Public
A19: PID0018 | B19: Master's Degree | C19: Doctor | D19: Startup
A20: PID0019 | B20: School | C20: Retail Worker | D20: Public
A21: PID0020 | B21: Bachelor's Degree | C21: Junior Executive | D21: Startup
A22: PID0021 | B22: High School | C22: Unemployed | D22: None
A23: PID0022 | B23: Master's Degree | C23: Senior Executive | D23: Private
A24: PID0023 | B24: PhD | C24: Scientist | D24: Public
A25: PID0024 | B25: Master's Degree | C25: Software Engineer | D25: Startup
A26: PID0025 | B26: School | C26: Retail Worker | D26: Public
... A1001: PID1000 | B1001: Bachelor's Degree | C1001: Teacher | D1001: Startup

Sheet Facts
A2: State | B2: Region
A3: Tamil Nadu | B3: South
A4: Maharashtra | B4: West
A5: Punjab | B5: North
A6: Karnataka | B6: South
A7: Uttar Pradesh | B7: North
A8: Kerala | B8: South
A9: West Bengal | B9: East
A10: Gujarat | B10: West

Sheet Patient Demographics
A1: Patient Id | B1: Patient Name | C1: Patient name (trimmed) | D1: Health report | E1: Gender | F1: Date of Birth | G1: Updated DOB | H1: DOB (Year) | I1: Age | J1: Age Group | K1: Income (LPA) | L1: Location (state) | M1: Region | N1: Updated Region | O1: Unique Region | P1: Count Of Patient | Q1: Priority Type | R1: unique regions | S1: High priority patients | T1: Tagging Patients | U1: region_s | V1: Immediate attention patients | W1: Location | X1: First name(find) | Y1: first_name | Z1: Mid name | AA1: Last name
A2: PID0001 | B2: Shreya Reddy | C2: =TRIM(B2) -> Shreya Reddy | D2: =_xlfn.CONCAT(A2,"_",Y2,".pdf") -> PID0001_Shreya.pdf | E2: Female | F2: 31/12/1973 | G2: =DATEVALUE(F2) -> 27029 | H2: =YEAR(G2) -> 1973 | I2: =2026-H2 -> 53 | J2: {=_xlfn.IFS(AND(I2>20,I2<=30),"Young adult",AND(I2>30,I2<=45),"Adult",AND(I2>45,I2<=60),"Senior",AND(I2>60,I2<90),"super senior",TRUE,"Died")} -> Senior | K2: 20 | L2: Tamil Nadu | M2: South | N2: =VLOOKUP(L2,Facts!$A$2:$B$10,2,FALSE) -> South | O2: {=_xlfn.UNIQUE(N2:N1001)} -> South | P2: =COUNTIF(N2:N1001,O2) -> 363 | Q2: =IF(AND(K2<=5,'Billing Details'!H2>=10000),"High Priority","Regularfollowup") -> Regularfollowup | R2: {=_xlfn.UNIQUE(N2:N1001)} -> South | S2: =COUNTIFS(N2:N1001,R2,Q2:Q1001,"High Priority") -> 51 | T2: =IF(AND(Q2="High Priority",'Patient Health Records'!AH2="Yes",'Patient Health Records'!AI2="Critical"), "Need Immediate attention", IF(AND('Patient Health Records'!AI2<>"Critical", 'Patient Health Records'!AH2="Yes"),"Monitor later",IF(AND('Patient Health Records'!AI2="Critical",'Patient Health Records'!AH2="No"),"Ask for readmission","No action"))) -> Ask for readmission | U2: {=_xlfn.UNIQUE(N2:N1001)} -> South | V2: =COUNTIFS(N2:N1001,U2,T2:T1001,"Need immediate attention") -> 11 | W2: =_xlfn.XLOOKUP('Patient Demographics'!N2,Facts!$B$2:$B$10,Facts!$A$2:$A$10,FALSE) -> Tamil Nadu | X2: =LEFT(C2,FIND(" ",C2)) -> Shreya | Y2: {=_xlfn.TEXTSPLIT(C2," ")} -> Shreya | Z2: Reddy
A3: PID0002 | B3: Isha Sharma | C3: =TRIM(B3) -> Isha Sharma | D3: =_xlfn.CONCAT(A3,"_",Y3,".pdf") -> PID0002_Isha.pdf | E3: Female | F3: 31/12/1953 | G3: =DATEVALUE(F3) -> 19724 | H3: =YEAR(G3) -> 1953 | I3: =2026-H3 -> 73 | J3: {=_xlfn.IFS(AND(I3>20,I3<=30),"Young adult",AND(I3>30,I3<=45),"Adult",AND(I3>45,I3<=60),"Senior",AND(I3>60,I3<90),"super senior",TRUE,"Died")} -> super senior | K3: 15 | L3: Maharashtra | M3: South | N3: =VLOOKUP(L3,Facts!$A$2:$B$10,2,FALSE) -> West | O3: West | P3: =COUNTIF(N3:N1002,O3) -> 249 | Q3: =IF(AND(K3<=5,'Billing Details'!H3>=10000),"High Priority","Regularfollowup") -> Regularfollowup | R3: West | S3: =COUNTIFS(N3:N1002,R3,Q3:Q1002,"High Priority") -> 20 | T3: =IF(AND(Q3="High Priority",'Patient Health Records'!AH3="Yes",'Patient Health Records'!AI3="Critical"), "Need Immediate attention", IF(AND('Patient Health Records'!AI3<>"Critical", 'Patient Health Records'!AH3="Yes"),"Monitor later",IF(AND('Patient Health Records'!AI3="Critical",'Patient Health Records'!AH3="No"),"Ask for readmission","No action"))) -> No action | U3: West | V3: =COUNTIFS(N3:N1002,U3,T3:T1002,"Need immediate attention") -> 5 | W3: =_xlfn.XLOOKUP('Patient Demographics'!N3,Facts!$B$2:$B$10,Facts!$A$2:$A$10,FALSE) -> Maharashtra | X3: =LEFT(C3,FIND(" ",C3)) -> Isha | Y3: {=_xlfn.TEXTSPLIT(C3," ")} -> Isha | Z3: Sharma
A4: PID0003 | B4: Isha Raj Reddy | C4: =TRIM(B4) -> Isha Raj Reddy | D4: =_xlfn.CONCAT(A4,"_",Y4,".pdf") -> PID0003_Isha.pdf | E4: Female | F4: 31/12/1993 | G4: =DATEVALUE(F4) -> 34334 | H4: =YEAR(G4) -> 1993 | I4: =2026-H4 -> 33 | J4: {=_xlfn.IFS(AND(I4>20,I4<=30),"Young adult",AND(I4>30,I4<=45),"Adult",AND(I4>45,I4<=60),"Senior",AND(I4>60,I4<90),"super senior",TRUE,"Died")} -> Adult | K4: 20 | L4: Punjab | M4: North | N4: =VLOOKUP(L4,Facts!$A$2:$B$10,2,FALSE) -> North | O4: North | P4: =COUNTIF(N4:N1003,O4) -> 252 | Q4: =IF(AND(K4<=5,'Billing Details'!H4>=10000),"High Priority","Regularfollowup") -> Regularfollowup | R4: North | S4: =COUNTIFS(N4:N1003,R4,Q4:Q1003,"High Priority") -> 93 | T4: =IF(AND(Q4="High Priority",'Patient Health Records'!AH4="Yes",'Patient Health Records'!AI4="Critical"), "Need Immediate attention", IF(AND('Patient Health Records'!AI4<>"Critical", 'Patient Health Records'!AH4="Yes"),"Monitor later",IF(AND('Patient Health Records'!AI4="Critical",'Patient Health Records'!AH4="No"),"Ask for readmission","No action"))) -> Ask for readmission | U4: North | V4: =COUNTIFS(N4:N1003,U4,T4:T1003,"Need immediate attention") -> 14 | W4: =_xlfn.XLOOKUP('Patient Demographics'!N4,Facts!$B$2:$B$10,Facts!$A$2:$A$10,FALSE) -> Punjab | X4: =LEFT(C4,FIND(" ",C4)) -> Isha | Y4: {=_xlfn.TEXTSPLIT(C4," ")} -> Isha | Z4: Raj | AA4: Reddy
A5: PID0004 | B5: Aditya Patel | C5: =TRIM(B5) -> Aditya Patel | D5: =_xlfn.CONCAT(A5,"_",Y5,".pdf") -> PID0004_Aditya.pdf | E5: Male | F5: 31/12/1993 | G5: =DATEVALUE(F5) -> 34334 | H5: =YEAR(G5) -> 1993 | I5: =2026-H5 -> 33 | J5: {=_xlfn.IFS(AND(I5>20,I5<=30),"Young adult",AND(I5>30,I5<=45),"Adult",AND(I5>45,I5<=60),"Senior",AND(I5>60,I5<90),"super senior",TRUE,"Died")} -> Adult | K5: 15 | L5: Karnataka | M5: South | N5: =VLOOKUP(L5,Facts!$A$2:$B$10,2,FALSE) -> South | O5: East | P5: =COUNTIF(N5:N1004,O5) -> 136 | Q5: =IF(AND(K5<=5,'Billing Details'!H5>=10000),"High Priority","Regularfollowup") -> Regularfollowup | R5: East | S5: =COUNTIFS(N5:N1004,R5,Q5:Q1004,"High Priority") -> 29 | T5: =IF(AND(Q5="High Priority",'Patient Health Records'!AH5="Yes",'Patient Health Records'!AI5="Critical"), "Need Immediate attention", IF(AND('Patient Health Records'!AI5<>"Critical", 'Patient Health Records'!AH5="Yes"),"Monitor later",IF(AND('Patient Health Records'!AI5="Critical",'Patient Health Records'!AH5="No"),"Ask for readmission","No action"))) -> Ask for readmission | U5: East | V5: =COUNTIFS(N5:N1004,U5,T5:T1004,"Need immediate attention") -> 4 | W5: =_xlfn.XLOOKUP('Patient Demographics'!N5,Facts!$B$2:$B$10,Facts!$A$2:$A$10,FALSE) -> Tamil Nadu | X5: =LEFT(C5,FIND(" ",C5)) -> Aditya | Y5: {=_xlfn.TEXTSPLIT(C5," ")} -> Aditya | Z5: Patel
A6: PID0005 | B6: Aarav Mehta | C6: =TRIM(B6) -> Aarav Mehta | D6: =_xlfn.CONCAT(A6,"_",Y6,".pdf") -> PID0005_Aarav.pdf | E6: Male | F6: 31/12/1988 | G6: =DATEVALUE(F6) -> 32508 | H6: =YEAR(G6) -> 1988 | I6: =2026-H6 -> 38 | J6: {=_xlfn.IFS(AND(I6>20,I6<=30),"Young adult",AND(I6>30,I6<=45),"Adult",AND(I6>45,I6<=60),"Senior",AND(I6>60,I6<90),"super senior",TRUE,"Died")} -> Adult | K6: 2 | L6: Uttar Pradesh | M6: North | N6: =VLOOKUP(L6,Facts!$A$2:$B$10,2,FALSE) -> North | Q6: =IF(AND(K6<=5,'Billing Details'!H6>=10000),"High Priority","Regularfollowup") -> Regularfollowup | T6: =IF(AND(Q6="High Priority",'Patient Health Records'!AH6="Yes",'Patient Health Records'!AI6="Critical"), "Need Immediate attention", IF(AND('Patient Health Records'!AI6<>"Critical", 'Patient Health Records'!AH6="Yes"),"Monitor later",IF(AND('Patient Health Records'!AI6="Critical",'Patient Health Records'!AH6="No"),"Ask for readmission","No action"))) -> No action | W6: =_xlfn.XLOOKUP('Patient Demographics'!N6,Facts!$B$2:$B$10,Facts!$A$2:$A$10,FALSE) -> Punjab | X6: =LEFT(C6,FIND(" ",C6)) -> Aarav | Y6: {=_xlfn.TEXTSPLIT(C6," ")} -> Aarav | Z6: Mehta
A7: PID0006 | B7: Aarav Sharma | C7: =TRIM(B7) -> Aarav Sharma | D7: =_xlfn.CONCAT(A7,"_",Y7,".pdf") -> PID0006_Aarav.pdf | E7: Male | F7: 31/12/1938 | G7: =DATEVALUE(F7) -> 14245 | H7: =YEAR(G7) -> 1938 | I7: =2026-H7 -> 88 | J7: {=_xlfn.IFS(AND(I7>20,I7<=30),"Young adult",AND(I7>30,I7<=45),"Adult",AND(I7>45,I7<=60),"Senior",AND(I7>60,I7<90),"super senior",TRUE,"Died")} -> super senior | K7: 20 | L7: Karnataka | M7: South | N7: =VLOOKUP(L7,Facts!$A$2:$B$10,2,FALSE) -> South | Q7: =IF(AND(K7<=5,'Billing Details'!H7>=10000),"High Priority","Regularfollowup") -> Regularfollowup | T7: =IF(AND(Q7="High Priority",'Patient Health Records'!AH7="Yes",'Patient Health Records'!AI7="Critical"), "Need Immediate attention", IF(AND('Patient Health Records'!AI7<>"Critical", 'Patient Health Records'!AH7="Yes"),"Monitor later",IF(AND('Patient Health Records'!AI7="Critical",'Patient Health Records'!AH7="No"),"Ask for readmission","No action"))) -> No action | W7: =_xlfn.XLOOKUP('Patient Demographics'!N7,Facts!$B$2:$B$10,Facts!$A$2:$A$10,FALSE) -> Tamil Nadu | X7: =LEFT(C7,FIND(" ",C7)) -> Aarav | Y7: {=_xlfn.TEXTSPLIT(C7," ")} -> Aarav | Z7: Sharma
A8: PID0007 | B8: Sai Raj Patel | C8: =TRIM(B8) -> Sai Raj Patel | D8: =_xlfn.CONCAT(A8,"_",Y8,".pdf") -> PID0007_Sai.pdf | E8: Male | F8: 31/12/1988 | G8: =DATEVALUE(F8) -> 32508 | H8: =YEAR(G8) -> 1988 | I8: =2026-H8 -> 38 | J8: {=_xlfn.IFS(AND(I8>20,I8<=30),"Young adult",AND(I8>30,I8<=45),"Adult",AND(I8>45,I8<=60),"Senior",AND(I8>60,I8<90),"super senior",TRUE,"Died")} -> Adult | K8: 40 | L8: Maharashtra | M8: North | N8: =VLOOKUP(L8,Facts!$A$2:$B$10,2,FALSE) -> West | Q8: =IF(AND(K8<=5,'Billing Details'!H8>=10000),"High Priority","Regularfollowup") -> Regularfollowup | T8: =IF(AND(Q8="High Priority",'Patient Health Records'!AH8="Yes",'Patient Health Records'!AI8="Critical"), "Need Immediate attention", IF(AND('Patient Health Records'!AI8<>"Critical", 'Patient Health Records'!AH8="Yes"),"Monitor later",IF(AND('Patient Health Records'!AI8="Critical",'Patient Health Records'!AH8="No"),"Ask for readmission","No action"))) -> No action | W8: =_xlfn.XLOOKUP('Patient Demographics'!N8,Facts!$B$2:$B$10,Facts!$A$2:$A$10,FALSE) -> Maharashtra | X8: =LEFT(C8,FIND(" ",C8)) -> Sai | Y8: {=_xlfn.TEXTSPLIT(C8," ")} -> Sai | Z8: Raj | AA8: Patel
A9: PID0008 | B9: Shreya Reddy | C9: =TRIM(B9) -> Shreya Reddy | D9: =_xlfn.CONCAT(A9,"_",Y9,".pdf") -> PID0008_Shreya.pdf | E9: Female | F9: 31/12/1994 | G9: =DATEVALUE(F9) -> 34699 | H9: =YEAR(G9) -> 1994 | I9: =2026-H9 -> 32 | J9: {=_xlfn.IFS(AND(I9>20,I9<=30),"Young adult",AND(I9>30,I9<=45),"Adult",AND(I9>45,I9<=60),"Senior",AND(I9>60,I9<90),"super senior",TRUE,"Died")} -> Adult | K9: 30 | L9: Kerala | M9: East | N9: =VLOOKUP(L9,Facts!$A$2:$B$10,2,FALSE) -> South | Q9: =IF(AND(K9<=5,'Billing Details'!H9>=10000),"High Priority","Regularfollowup") -> Regularfollowup | T9: =IF(AND(Q9="High Priority",'Patient Health Records'!AH9="Yes",'Patient Health Records'!AI9="Critical"), "Need Immediate attention", IF(AND('Patient Health Records'!AI9<>"Critical", 'Patient Health Records'!AH9="Yes"),"Monitor later",IF(AND('Patient Health Records'!AI9="Critical",'Patient Health Records'!AH9="No"),"Ask for readmission","No action"))) -> Monitor later | W9: =_xlfn.XLOOKUP('Patient Demographics'!N9,Facts!$B$2:$B$10,Facts!$A$2:$A$10,FALSE) -> Tamil Nadu | X9: =LEFT(C9,FIND(" ",C9)) -> Shreya | Y9: {=_xlfn.TEXTSPLIT(C9," ")} -> Shreya | Z9: Reddy
A10: PID0009 | B10: Diya Mehta | C10: =TRIM(B10) -> Diya Mehta | D10: =_xlfn.CONCAT(A10,"_",Y10,".pdf") -> PID0009_Diya.pdf | E10: Female | F10: 31/12/1978 | G10: =DATEVALUE(F10) -> 28855 | H10: =YEAR(G10) -> 1978 | I10: =2026-H10 -> 48 | J10: {=_xlfn.IFS(AND(I10>20,I10<=30),"Young adult",AND(I10>30,I10<=45),"Adult",AND(I10>45,I10<=60),"Senior",AND(I10>60,I10<90),"super senior",TRUE,"Died")} -> Senior | K10: 20 | L10: Karnataka | M10: South | N10: =VLOOKUP(L10,Facts!$A$2:$B$10,2,FALSE) -> South | Q10: =IF(AND(K10<=5,'Billing Details'!H10>=10000),"High Priority","Regularfollowup") -> Regularfollowup | T10: =IF(AND(Q10="High Priority",'Patient Health Records'!AH10="Yes",'Patient Health Records'!AI10="Critical"), "Need Immediate attention", IF(AND('Patient Health Records'!AI10<>"Critical", 'Patient Health Records'!AH10="Yes"),"Monitor later",IF(AND('Patient Health Records'!AI10="Critical",'Patient Health Records'!AH10="No"),"Ask for readmission","No action"))) -> No action | W10: =_xlfn.XLOOKUP('Patient Demographics'!N10,Facts!$B$2:$B$10,Facts!$A$2:$A$10,FALSE) -> Tamil Nadu | X10: =LEFT(C10,FIND(" ",C10)) -> Diya | Y10: {=_xlfn.TEXTSPLIT(C10," ")} -> Diya | Z10: Mehta
A11: PID0010 | B11: Vivaan Patel | C11: =TRIM(B11) -> Vivaan Patel | D11: =_xlfn.CONCAT(A11,"_",Y11,".pdf") -> PID0010_Vivaan.pdf | E11: Male | F11: 31-12-1994 | G11: =DATEVALUE(F11) -> 34699 | H11: =YEAR(G11) -> 1994 | I11: =2026-H11 -> 32 | J11: {=_xlfn.IFS(AND(I11>20,I11<=30),"Young adult",AND(I11>30,I11<=45),"Adult",AND(I11>45,I11<=60),"Senior",AND(I11>60,I11<90),"super senior",TRUE,"Died")} -> Adult | K11: 2 | L11: West Bengal | M11: East | N11: =VLOOKUP(L11,Facts!$A$2:$B$10,2,FALSE) -> East | Q11: =IF(AND(K11<=5,'Billing Details'!H11>=10000),"High Priority","Regularfollowup") -> High Priority | T11: =IF(AND(Q11="High Priority",'Patient Health Records'!AH11="Yes",'Patient Health Records'!AI11="Critical"), "Need Immediate attention", IF(AND('Patient Health Records'!AI11<>"Critical", 'Patient Health Records'!AH11="Yes"),"Monitor later",IF(AND('Patient Health Records'!AI11="Critical",'Patient Health Records'!AH11="No"),"Ask for readmission","No action"))) -> Ask for readmission | W11: =_xlfn.XLOOKUP('Patient Demographics'!N11,Facts!$B$2:$B$10,Facts!$A$2:$A$10,FALSE) -> West Bengal | X11: =LEFT(C11,FIND(" ",C11)) -> Vivaan | Y11: {=_xlfn.TEXTSPLIT(C11," ")} -> Vivaan | Z11: Patel
A12: PID0011 | B12: Aditya Gupta | C12: =TRIM(B12) -> Aditya Gupta | D12: =_xlfn.CONCAT(A12,"_",Y12,".pdf") -> PID0011_Aditya.pdf | E12: Male | F12: 01/01/1964 | G12: =DATEVALUE(F12) -> 23377 | H12: =YEAR(G12) -> 1964 | I12: =2026-H12 -> 62 | J12: {=_xlfn.IFS(AND(I12>20,I12<=30),"Young adult",AND(I12>30,I12<=45),"Adult",AND(I12>45,I12<=60),"Senior",AND(I12>60,I12<90),"super senior",TRUE,"Died")} -> super senior | K12: 3 | L12: Karnataka | M12: North | N12: =VLOOKUP(L12,Facts!$A$2:$B$10,2,FALSE) -> South | Q12: =IF(AND(K12<=5,'Billing Details'!H12>=10000),"High Priority","Regularfollowup") -> Regularfollowup | T12: =IF(AND(Q12="High Priority",'Patient Health Records'!AH12="Yes",'Patient Health Records'!AI12="Critical"), "Need Immediate attention", IF(AND('Patient Health Records'!AI12<>"Critical", 'Patient Health Records'!AH12="Yes"),"Monitor later",IF(AND('Patient Health Records'!AI12="Critical",'Patient Health Records'!AH12="No"),"Ask for readmission","No action"))) -> No action | W12: =_xlfn.XLOOKUP('Patient Demographics'!N12,Facts!$B$2:$B$10,Facts!$A$2:$A$10,FALSE) -> Tamil Nadu | X12: =LEFT(C12,FIND(" ",C12)) -> Aditya | Y12: {=_xlfn.TEXTSPLIT(C12," ")} -> Aditya | Z12: Gupta
A13: PID0012 | B13: Aditya Sharma | C13: =TRIM(B13) -> Aditya Sharma | D13: =_xlfn.CONCAT(A13,"_",Y13,".pdf") -> PID0012_Aditya.pdf | E13: Male | F13: 01/01/1964 | G13: =DATEVALUE(F13) -> 23377 | H13: =YEAR(G13) -> 1964 | I13: =2026-H13 -> 62 | J13: {=_xlfn.IFS(AND(I13>20,I13<=30),"Young adult",AND(I13>30,I13<=45),"Adult",AND(I13>45,I13<=60),"Senior",AND(I13>60,I13<90),"super senior",TRUE,"Died")} -> super senior | K13: 15 | L13: Tamil Nadu | M13: South | N13: =VLOOKUP(L13,Facts!$A$2:$B$10,2,FALSE) -> South | Q13: =IF(AND(K13<=5,'Billing Details'!H13>=10000),"High Priority","Regularfollowup") -> Regularfollowup | T13: =IF(AND(Q13="High Priority",'Patient Health Records'!AH13="Yes",'Patient Health Records'!AI13="Critical"), "Need Immediate attention", IF(AND('Patient Health Records'!AI13<>"Critical", 'Patient Health Records'!AH13="Yes"),"Monitor later",IF(AND('Patient Health Records'!AI13="Critical",'Patient Health Records'!AH13="No"),"Ask for readmission","No action"))) -> Monitor later | W13: =_xlfn.XLOOKUP('Patient Demographics'!N13,Facts!$B$2:$B$10,Facts!$A$2:$A$10,FALSE) -> Tamil Nadu | X13: =LEFT(C13,FIND(" ",C13)) -> Aditya | Y13: {=_xlfn.TEXTSPLIT(C13," ")} -> Aditya | Z13: Sharma
A14: PID0013 | B14: Diya Kumar Sharma | C14: =TRIM(B14) -> Diya Kumar Sharma | D14: =_xlfn.CONCAT(A14,"_",Y14,".pdf") -> PID0013_Diya.pdf | E14: Female | F14: 31/12/1973 | G14: =DATEVALUE(F14) -> 27029 | H14: =YEAR(G14) -> 1973 | I14: =2026-H14 -> 53 | J14: {=_xlfn.IFS(AND(I14>20,I14<=30),"Young adult",AND(I14>30,I14<=45),"Adult",AND(I14>45,I14<=60),"Senior",AND(I14>60,I14<90),"super senior",TRUE,"Died")} -> Senior | K14: 7 | L14: Kerala | M14: North | N14: =VLOOKUP(L14,Facts!$A$2:$B$10,2,FALSE) -> South | Q14: =IF(AND(K14<=5,'Billing Details'!H14>=10000),"High Priority","Regularfollowup") -> Regularfollowup | T14: =IF(AND(Q14="High Priority",'Patient Health Records'!AH14="Yes",'Patient Health Records'!AI14="Critical"), "Need Immediate attention", IF(AND('Patient Health Records'!AI14<>"Critical", 'Patient Health Records'!AH14="Yes"),"Monitor later",IF(AND('Patient Health Records'!AI14="Critical",'Patient Health Records'!AH14="No"),"Ask for readmission","No action"))) -> Monitor later | W14: =_xlfn.XLOOKUP('Patient Demographics'!N14,Facts!$B$2:$B$10,Facts!$A$2:$A$10,FALSE) -> Tamil Nadu | X14: =LEFT(C14,FIND(" ",C14)) -> Diya | Y14: {=_xlfn.TEXTSPLIT(C14," ")} -> Diya | Z14: Kumar | AA14: Sharma
A15: PID0014 | B15: Aanya Raj Sharma | C15: =TRIM(B15) -> Aanya Raj Sharma | D15: =_xlfn.CONCAT(A15,"_",Y15,".pdf") -> PID0014_Aanya.pdf | E15: Female | F15: 31/12/1981 | G15: =DATEVALUE(F15) -> 29951 | H15: =YEAR(G15) -> 1981 | I15: =2026-H15 -> 45 | J15: {=_xlfn.IFS(AND(I15>20,I15<=30),"Young adult",AND(I15>30,I15<=45),"Adult",AND(I15>45,I15<=60),"Senior",AND(I15>60,I15<90),"super senior",TRUE,"Died")} -> Adult | K15: 15 | L15: Kerala | M15: South | N15: =VLOOKUP(L15,Facts!$A$2:$B$10,2,FALSE) -> South | Q15: =IF(AND(K15<=5,'Billing Details'!H15>=10000),"High Priority","Regularfollowup") -> Regularfollowup | T15: =IF(AND(Q15="High Priority",'Patient Health Records'!AH15="Yes",'Patient Health Records'!AI15="Critical"), "Need Immediate attention", IF(AND('Patient Health Records'!AI15<>"Critical", 'Patient Health Records'!AH15="Yes"),"Monitor later",IF(AND('Patient Health Records'!AI15="Critical",'Patient Health Records'!AH15="No"),"Ask for readmission","No action"))) -> No action | W15: =_xlfn.XLOOKUP('Patient Demographics'!N15,Facts!$B$2:$B$10,Facts!$A$2:$A$10,FALSE) -> Tamil Nadu | X15: =LEFT(C15,FIND(" ",C15)) -> Aanya | Y15: {=_xlfn.TEXTSPLIT(C15," ")} -> Aanya | Z15: Raj | AA15: Sharma
A16: PID0015 | B16: Diya Priya Gupta | C16: =TRIM(B16) -> Diya Priya Gupta | D16: =_xlfn.CONCAT(A16,"_",Y16,".pdf") -> PID0015_Diya.pdf | E16: Female | F16: 01/01/1964 | G16: =DATEVALUE(F16) -> 23377 | H16: =YEAR(G16) -> 1964 | I16: =2026-H16 -> 62 | J16: {=_xlfn.IFS(AND(I16>20,I16<=30),"Young adult",AND(I16>30,I16<=45),"Adult",AND(I16>45,I16<=60),"Senior",AND(I16>60,I16<90),"super senior",TRUE,"Died")} -> super senior | K16: 2 | L16: Uttar Pradesh | M16: North | N16: =VLOOKUP(L16,Facts!$A$2:$B$10,2,FALSE) -> North | Q16: =IF(AND(K16<=5,'Billing Details'!H16>=10000),"High Priority","Regularfollowup") -> High Priority | T16: =IF(AND(Q16="High Priority",'Patient Health Records'!AH16="Yes",'Patient Health Records'!AI16="Critical"), "Need Immediate attention", IF(AND('Patient Health Records'!AI16<>"Critical", 'Patient Health Records'!AH16="Yes"),"Monitor later",IF(AND('Patient Health Records'!AI16="Critical",'Patient Health Records'!AH16="No"),"Ask for readmission","No action"))) -> Ask for readmission | W16: =_xlfn.XLOOKUP('Patient Demographics'!N16,Facts!$B$2:$B$10,Facts!$A$2:$A$10,FALSE) -> Punjab | X16: =LEFT(C16,FIND(" ",C16)) -> Diya | Y16: {=_xlfn.TEXTSPLIT(C16," ")} -> Diya | Z16: Priya | AA16: Gupta
A17: PID0016 | B17: Isha Kumar Mehta | C17: =TRIM(B17) -> Isha Kumar Mehta | D17: =_xlfn.CONCAT(A17,"_",Y17,".pdf") -> PID0016_Isha.pdf | E17: Female | F17: 31/12/1994 | G17: =DATEVALUE(F17) -> 34699 | H17: =YEAR(G17) -> 1994 | I17: =2026-H17 -> 32 | J17: {=_xlfn.IFS(AND(I17>20,I17<=30),"Young adult",AND(I17>30,I17<=45),"Adult",AND(I17>45,I17<=60),"Senior",AND(I17>60,I17<90),"super senior",TRUE,"Died")} -> Adult | K17: 15 | L17: Gujarat | M17: South | N17: =VLOOKUP(L17,Facts!$A$2:$B$10,2,FALSE) -> West | Q17: =IF(AND(K17<=5,'Billing Details'!H17>=10000),"High Priority","Regularfollowup") -> Regularfollowup | T17: =IF(AND(Q17="High Priority",'Patient Health Records'!AH17="Yes",'Patient Health Records'!AI17="Critical"), "Need Immediate attention", IF(AND('Patient Health Records'!AI17<>"Critical", 'Patient Health Records'!AH17="Yes"),"Monitor later",IF(AND('Patient Health Records'!AI17="Critical",'Patient Health Records'!AH17="No"),"Ask for readmission","No action"))) -> Monitor later | W17: =_xlfn.XLOOKUP('Patient Demographics'!N17,Facts!$B$2:$B$10,Facts!$A$2:$A$10,FALSE) -> Maharashtra | X17: =LEFT(C17,FIND(" ",C17)) -> Isha | Y17: {=_xlfn.TEXTSPLIT(C17," ")} -> Isha | Z17: Kumar | AA17: Mehta
A18: PID0017 | B18: Aditya Patel | C18: =TRIM(B18) -> Aditya Patel | D18: =_xlfn.CONCAT(A18,"_",Y18,".pdf") -> PID0017_Aditya.pdf | E18: Male | F18: 01/01/1984 | G18: =DATEVALUE(F18) -> 30682 | H18: =YEAR(G18) -> 1984 | I18: =2026-H18 -> 42 | J18: {=_xlfn.IFS(AND(I18>20,I18<=30),"Young adult",AND(I18>30,I18<=45),"Adult",AND(I18>45,I18<=60),"Senior",AND(I18>60,I18<90),"super senior",TRUE,"Died")} -> Adult | K18: 7 | L18: Kerala | M18: South | N18: =VLOOKUP(L18,Facts!$A$2:$B$10,2,FALSE) -> South | Q18: =IF(AND(K18<=5,'Billing Details'!H18>=10000),"High Priority","Regularfollowup") -> Regularfollowup | T18: =IF(AND(Q18="High Priority",'Patient Health Records'!AH18="Yes",'Patient Health Records'!AI18="Critical"), "Need Immediate attention", IF(AND('Patient Health Records'!AI18<>"Critical", 'Patient Health Records'!AH18="Yes"),"Monitor later",IF(AND('Patient Health Records'!AI18="Critical",'Patient Health Records'!AH18="No"),"Ask for readmission","No action"))) -> No action | W18: =_xlfn.XLOOKUP('Patient Demographics'!N18,Facts!$B$2:$B$10,Facts!$A$2:$A$10,FALSE) -> Tamil Nadu | X18: =LEFT(C18,FIND(" ",C18)) -> Aditya | Y18: {=_xlfn.TEXTSPLIT(C18," ")} -> Aditya | Z18: Patel
A19: PID0018 | B19: Riya Kumar Gupta | C19: =TRIM(B19) -> Riya Kumar Gupta | D19: =_xlfn.CONCAT(A19,"_",Y19,".pdf") -> PID0018_Riya.pdf | E19: Female | F19: 31/12/1968 | G19: =DATEVALUE(F19) -> 25203 | H19: =YEAR(G19) -> 1968 | I19: =2026-H19 -> 58 | J19: {=_xlfn.IFS(AND(I19>20,I19<=30),"Young adult",AND(I19>30,I19<=45),"Adult",AND(I19>45,I19<=60),"Senior",AND(I19>60,I19<90),"super senior",TRUE,"Died")} -> Senior | K19: 3 | L19: Karnataka | M19: East | N19: =VLOOKUP(L19,Facts!$A$2:$B$10,2,FALSE) -> South | Q19: =IF(AND(K19<=5,'Billing Details'!H19>=10000),"High Priority","Regularfollowup") -> Regularfollowup | T19: =IF(AND(Q19="High Priority",'Patient Health Records'!AH19="Yes",'Patient Health Records'!AI19="Critical"), "Need Immediate attention", IF(AND('Patient Health Records'!AI19<>"Critical", 'Patient Health Records'!AH19="Yes"),"Monitor later",IF(AND('Patient Health Records'!AI19="Critical",'Patient Health Records'!AH19="No"),"Ask for readmission","No action"))) -> Ask for readmission | W19: =_xlfn.XLOOKUP('Patient Demographics'!N19,Facts!$B$2:$B$10,Facts!$A$2:$A$10,FALSE) -> Tamil Nadu | X19: =LEFT(C19,FIND(" ",C19)) -> Riya | Y19: {=_xlfn.TEXTSPLIT(C19," ")} -> Riya | Z19: Kumar | AA19: Gupta
A20: PID0019 | B20: Shreya Sharma | C20: =TRIM(B20) -> Shreya Sharma | D20: =_xlfn.CONCAT(A20,"_",Y20,".pdf") -> PID0019_Shreya.pdf | E20: Female | F20: 31/12/1981 | G20: =DATEVALUE(F20) -> 29951 | H20: =YEAR(G20) -> 1981 | I20: =2026-H20 -> 45 | J20: {=_xlfn.IFS(AND(I20>20,I20<=30),"Young adult",AND(I20>30,I20<=45),"Adult",AND(I20>45,I20<=60),"Senior",AND(I20>60,I20<90),"super senior",TRUE,"Died")} -> Adult | K20: 4 | L20: Karnataka | M20: South | N20: =VLOOKUP(L20,Facts!$A$2:$B$10,2,FALSE) -> South | Q20: =IF(AND(K20<=5,'Billing Details'!H20>=10000),"High Priority","Regularfollowup") -> Regularfollowup | T20: =IF(AND(Q20="High Priority",'Patient Health Records'!AH20="Yes",'Patient Health Records'!AI20="Critical"), "Need Immediate attention", IF(AND('Patient Health Records'!AI20<>"Critical", 'Patient Health Records'!AH20="Yes"),"Monitor later",IF(AND('Patient Health Records'!AI20="Critical",'Patient Health Records'!AH20="No"),"Ask for readmission","No action"))) -> No action | W20: =_xlfn.XLOOKUP('Patient Demographics'!N20,Facts!$B$2:$B$10,Facts!$A$2:$A$10,FALSE) -> Tamil Nadu | X20: =LEFT(C20,FIND(" ",C20)) -> Shreya | Y20: {=_xlfn.TEXTSPLIT(C20," ")} -> Shreya | Z20: Sharma
A21: PID0020 | B21: Krishna Patel | C21: =TRIM(B21) -> Krishna Patel | D21: =_xlfn.CONCAT(A21,"_",Y21,".pdf") -> PID0020_Krishna.pdf | E21: Male | F21: 31-12-1968 | G21: =DATEVALUE(F21) -> 25203 | H21: =YEAR(G21) -> 1968 | I21: =2026-H21 -> 58 | J21: {=_xlfn.IFS(AND(I21>20,I21<=30),"Young adult",AND(I21>30,I21<=45),"Adult",AND(I21>45,I21<=60),"Senior",AND(I21>60,I21<90),"super senior",TRUE,"Died")} -> Senior | K21: 15 | L21: Maharashtra | M21: West | N21: =VLOOKUP(L21,Facts!$A$2:$B$10,2,FALSE) -> West | Q21: =IF(AND(K21<=5,'Billing Details'!H21>=10000),"High Priority","Regularfollowup") -> Regularfollowup | T21: =IF(AND(Q21="High Priority",'Patient Health Records'!AH21="Yes",'Patient Health Records'!AI21="Critical"), "Need Immediate attention", IF(AND('Patient Health Records'!AI21<>"Critical", 'Patient Health Records'!AH21="Yes"),"Monitor later",IF(AND('Patient Health Records'!AI21="Critical",'Patient Health Records'!AH21="No"),"Ask for readmission","No action"))) -> No action | W21: =_xlfn.XLOOKUP('Patient Demographics'!N21,Facts!$B$2:$B$10,Facts!$A$2:$A$10,FALSE) -> Maharashtra | X21: =LEFT(C21,FIND(" ",C21)) -> Krishna | Y21: {=_xlfn.TEXTSPLIT(C21," ")} -> Krishna | Z21: Patel
A22: PID0021 | B22: Aanya Reddy | C22: =TRIM(B22) -> Aanya Reddy | D22: =_xlfn.CONCAT(A22,"_",Y22,".pdf") -> PID0021_Aanya.pdf | E22: Female | F22: 31/12/1980 | G22: =DATEVALUE(F22) -> 29586 | H22: =YEAR(G22) -> 1980 | I22: =2026-H22 -> 46 | J22: {=_xlfn.IFS(AND(I22>20,I22<=30),"Young adult",AND(I22>30,I22<=45),"Adult",AND(I22>45,I22<=60),"Senior",AND(I22>60,I22<90),"super senior",TRUE,"Died")} -> Senior | K22: 30 | L22: Punjab | M22: North | N22: =VLOOKUP(L22,Facts!$A$2:$B$10,2,FALSE) -> North | Q22: =IF(AND(K22<=5,'Billing Details'!H22>=10000),"High Priority","Regularfollowup") -> Regularfollowup | T22: =IF(AND(Q22="High Priority",'Patient Health Records'!AH22="Yes",'Patient Health Records'!AI22="Critical"), "Need Immediate attention", IF(AND('Patient Health Records'!AI22<>"Critical", 'Patient Health Records'!AH22="Yes"),"Monitor later",IF(AND('Patient Health Records'!AI22="Critical",'Patient Health Records'!AH22="No"),"Ask for readmission","No action"))) -> No action | W22: =_xlfn.XLOOKUP('Patient Demographics'!N22,Facts!$B$2:$B$10,Facts!$A$2:$A$10,FALSE) -> Punjab | X22: =LEFT(C22,FIND(" ",C22)) -> Aanya | Y22: {=_xlfn.TEXTSPLIT(C22," ")} -> Aanya | Z22: Reddy
A23: PID0022 | B23: Diya Reddy | C23: =TRIM(B23) -> Diya Reddy | D23: =_xlfn.CONCAT(A23,"_",Y23,".pdf") -> PID0022_Diya.pdf | E23: Female | F23: 31/12/1978 | G23: =DATEVALUE(F23) -> 28855 | H23: =YEAR(G23) -> 1978 | I23: =2026-H23 -> 48 | J23: {=_xlfn.IFS(AND(I23>20,I23<=30),"Young adult",AND(I23>30,I23<=45),"Adult",AND(I23>45,I23<=60),"Senior",AND(I23>60,I23<90),"super senior",TRUE,"Died")} -> Senior | K23: 2 | L23: Karnataka | M23: South | N23: =VLOOKUP(L23,Facts!$A$2:$B$10,2,FALSE) -> South | Q23: =IF(AND(K23<=5,'Billing Details'!H23>=10000),"High Priority","Regularfollowup") -> High Priority | T23: =IF(AND(Q23="High Priority",'Patient Health Records'!AH23="Yes",'Patient Health Records'!AI23="Critical"), "Need Immediate attention", IF(AND('Patient Health Records'!AI23<>"Critical", 'Patient Health Records'!AH23="Yes"),"Monitor later",IF(AND('Patient Health Records'!AI23="Critical",'Patient Health Records'!AH23="No"),"Ask for readmission","No action"))) -> Monitor later | W23: =_xlfn.XLOOKUP('Patient Demographics'!N23,Facts!$B$2:$B$10,Facts!$A$2:$A$10,FALSE) -> Tamil Nadu | X23: =LEFT(C23,FIND(" ",C23)) -> Diya | Y23: {=_xlfn.TEXTSPLIT(C23," ")} -> Diya | Z23: Reddy
A24: PID0023 | B24: Vivaan Dev Sharma | C24: =TRIM(B24) -> Vivaan Dev Sharma | D24: =_xlfn.CONCAT(A24,"_",Y24,".pdf") -> PID0023_Vivaan.pdf | E24: Male | F24: 31/12/1968 | G24: =DATEVALUE(F24) -> 25203 | H24: =YEAR(G24) -> 1968 | I24: =2026-H24 -> 58 | J24: {=_xlfn.IFS(AND(I24>20,I24<=30),"Young adult",AND(I24>30,I24<=45),"Adult",AND(I24>45,I24<=60),"Senior",AND(I24>60,I24<90),"super senior",TRUE,"Died")} -> Senior | K24: 40 | L24: Karnataka | M24: South | N24: =VLOOKUP(L24,Facts!$A$2:$B$10,2,FALSE) -> South | Q24: =IF(AND(K24<=5,'Billing Details'!H24>=10000),"High Priority","Regularfollowup") -> Regularfollowup | T24: =IF(AND(Q24="High Priority",'Patient Health Records'!AH24="Yes",'Patient Health Records'!AI24="Critical"), "Need Immediate attention", IF(AND('Patient Health Records'!AI24<>"Critical", 'Patient Health Records'!AH24="Yes"),"Monitor later",IF(AND('Patient Health Records'!AI24="Critical",'Patient Health Records'!AH24="No"),"Ask for readmission","No action"))) -> No action | W24: =_xlfn.XLOOKUP('Patient Demographics'!N24,Facts!$B$2:$B$10,Facts!$A$2:$A$10,FALSE) -> Tamil Nadu | X24: =LEFT(C24,FIND(" ",C24)) -> Vivaan | Y24: {=_xlfn.TEXTSPLIT(C24," ")} -> Vivaan | Z24: Dev | AA24: Sharma
A25: PID0024 | B25: Aarav Mehta | C25: =TRIM(B25) -> Aarav Mehta | D25: =_xlfn.CONCAT(A25,"_",Y25,".pdf") -> PID0024_Aarav.pdf | E25: Male | F25: 01/01/1964 | G25: =DATEVALUE(F25) -> 23377 | H25: =YEAR(G25) -> 1964 | I25: =2026-H25 -> 62 | J25: {=_xlfn.IFS(AND(I25>20,I25<=30),"Young adult",AND(I25>30,I25<=45),"Adult",AND(I25>45,I25<=60),"Senior",AND(I25>60,I25<90),"super senior",TRUE,"Died")} -> super senior | K25: 15 | L25: Maharashtra | M25: North | N25: =VLOOKUP(L25,Facts!$A$2:$B$10,2,FALSE) -> West | Q25: =IF(AND(K25<=5,'Billing Details'!H25>=10000),"High Priority","Regularfollowup") -> Regularfollowup | T25: =IF(AND(Q25="High Priority",'Patient Health Records'!AH25="Yes",'Patient Health Records'!AI25="Critical"), "Need Immediate attention", IF(AND('Patient Health Records'!AI25<>"Critical", 'Patient Health Records'!AH25="Yes"),"Monitor later",IF(AND('Patient Health Records'!AI25="Critical",'Patient Health Records'!AH25="No"),"Ask for readmission","No action"))) -> No action | W25: =_xlfn.XLOOKUP('Patient Demographics'!N25,Facts!$B$2:$B$10,Facts!$A$2:$A$10,FALSE) -> Maharashtra | X25: =LEFT(C25,FIND(" ",C25)) -> Aarav | Y25: {=_xlfn.TEXTSPLIT(C25," ")} -> Aarav | Z25: Mehta
A26: PID0025 | B26: Vivaan Kumar Patel | C26: =TRIM(B26) -> Vivaan Kumar Patel | D26: =_xlfn.CONCAT(A26,"_",Y26,".pdf") -> PID0025_Vivaan.pdf | E26: Male | F26: 31/12/1988 | G26: =DATEVALUE(F26) -> 32508 | H26: =YEAR(G26) -> 1988 | I26: =2026-H26 -> 38 | J26: {=_xlfn.IFS(AND(I26>20,I26<=30),"Young adult",AND(I26>30,I26<=45),"Adult",AND(I26>45,I26<=60),"Senior",AND(I26>60,I26<90),"super senior",TRUE,"Died")} -> Adult | K26: 12 | L26: Maharashtra | M26: North | N26: =VLOOKUP(L26,Facts!$A$2:$B$10,2,FALSE) -> West | Q26: =IF(AND(K26<=5,'Billing Details'!H26>=10000),"High Priority","Regularfollowup") -> Regularfollowup | T26: =IF(AND(Q26="High Priority",'Patient Health Records'!AH26="Yes",'Patient Health Records'!AI26="Critical"), "Need Immediate attention", IF(AND('Patient Health Records'!AI26<>"Critical", 'Patient Health Records'!AH26="Yes"),"Monitor later",IF(AND('Patient Health Records'!AI26="Critical",'Patient Health Records'!AH26="No"),"Ask for readmission","No action"))) -> Monitor later | W26: =_xlfn.XLOOKUP('Patient Demographics'!N26,Facts!$B$2:$B$10,Facts!$A$2:$A$10,FALSE) -> Maharashtra | X26: =LEFT(C26,FIND(" ",C26)) -> Vivaan | Y26: {=_xlfn.TEXTSPLIT(C26," ")} -> Vivaan | Z26: Kumar | AA26: Patel
A27: PID0026 | B27: Aanya Priya Reddy | C27: =TRIM(B27) -> Aanya Priya Reddy | D27: =_xlfn.CONCAT(A27,"_",Y27,".pdf") -> PID0026_Aanya.pdf | E27: Female | F27: 31/12/1968 | G27: =DATEVALUE(F27) -> 25203 | H27: =YEAR(G27) -> 1968 | I27: =2026-H27 -> 58 | J27: {=_xlfn.IFS(AND(I27>20,I27<=30),"Young adult",AND(I27>30,I27<=45),"Adult",AND(I27>45,I27<=60),"Senior",AND(I27>60,I27<90),"super senior",TRUE,"Died")} -> Senior | K27: 2 | L27: Uttar Pradesh | M27: North | N27: =VLOOKUP(L27,Facts!$A$2:$B$10,2,FALSE) -> North | Q27: =IF(AND(K27<=5,'Billing Details'!H27>=10000),"High Priority","Regularfollowup") -> High Priority | T27: =IF(AND(Q27="High Priority",'Patient Health Records'!AH27="Yes",'Patient Health Records'!AI27="Critical"), "Need Immediate attention", IF(AND('Patient Health Records'!AI27<>"Critical", 'Patient Health Records'!AH27="Yes"),"Monitor later",IF(AND('Patient Health Records'!AI27="Critical",'Patient Health Records'!AH27="No"),"Ask for readmission","No action"))) -> No action | W27: =_xlfn.XLOOKUP('Patient Demographics'!N27,Facts!$B$2:$B$10,Facts!$A$2:$A$10,FALSE) -> Punjab | X27: =LEFT(C27,FIND(" ",C27)) -> Aanya | Y27: {=_xlfn.TEXTSPLIT(C27," ")} -> Aanya | Z27: Priya | AA27: Reddy
A28: PID0027 | B28: Riya Mehta | C28: =TRIM(B28) -> Riya Mehta | D28: =_xlfn.CONCAT(A28,"_",Y28,".pdf") -> PID0027_Riya.pdf | E28: Female | F28: 31-12-1978 | G28: =DATEVALUE(F28) -> 28855 | H28: =YEAR(G28) -> 1978 | I28: =2026-H28 -> 48 | J28: {=_xlfn.IFS(AND(I28>20,I28<=30),"Young adult",AND(I28>30,I28<=45),"Adult",AND(I28>45,I28<=60),"Senior",AND(I28>60,I28<90),"super senior",TRUE,"Died")} -> Senior | L28: Gujarat | M28: East | N28: =VLOOKUP(L28,Facts!$A$2:$B$10,2,FALSE) -> West | Q28: =IF(AND(K28<=5,'Billing Details'!H28>=10000),"High Priority","Regularfollowup") -> High Priority | T28: =IF(AND(Q28="High Priority",'Patient Health Records'!AH28="Yes",'Patient Health Records'!AI28="Critical"), "Need Immediate attention", IF(AND('Patient Health Records'!AI28<>"Critical", 'Patient Health Records'!AH28="Yes"),"Monitor later",IF(AND('Patient Health Records'!AI28="Critical",'Patient Health Records'!AH28="No"),"Ask for readmission","No action"))) -> Need Immediate attention | W28: =_xlfn.XLOOKUP('Patient Demographics'!N28,Facts!$B$2:$B$10,Facts!$A$2:$A$10,FALSE) -> Maharashtra | X28: =LEFT(C28,FIND(" ",C28)) -> Riya | Y28: {=_xlfn.TEXTSPLIT(C28," ")} -> Riya | Z28: Mehta
A29: PID0028 | B29: Aarav Sharma | C29: =TRIM(B29) -> Aarav Sharma | D29: =_xlfn.CONCAT(A29,"_",Y29,".pdf") -> PID0028_Aarav.pdf | E29: Male | F29: 31/12/1993 | G29: =DATEVALUE(F29) -> 34334 | H29: =YEAR(G29) -> 1993 | I29: =2026-H29 -> 33 | J29: {=_xlfn.IFS(AND(I29>20,I29<=30),"Young adult",AND(I29>30,I29<=45),"Adult",AND(I29>45,I29<=60),"Senior",AND(I29>60,I29<90),"super senior",TRUE,"Died")} -> Adult | K29: 25 | L29: Karnataka | M29: West | N29: =VLOOKUP(L29,Facts!$A$2:$B$10,2,FALSE) -> South | Q29: =IF(AND(K29<=5,'Billing Details'!H29>=10000),"High Priority","Regularfollowup") -> Regularfollowup | T29: =IF(AND(Q29="High Priority",'Patient Health Records'!AH29="Yes",'Patient Health Records'!AI29="Critical"), "Need Immediate attention", IF(AND('Patient Health Records'!AI29<>"Critical", 'Patient Health Records'!AH29="Yes"),"Monitor later",IF(AND('Patient Health Records'!AI29="Critical",'Patient Health Records'!AH29="No"),"Ask for readmission","No action"))) -> Monitor later | W29: =_xlfn.XLOOKUP('Patient Demographics'!N29,Facts!$B$2:$B$10,Facts!$A$2:$A$10,FALSE) -> Tamil Nadu | X29: =LEFT(C29,FIND(" ",C29)) -> Aarav | Y29: {=_xlfn.TEXTSPLIT(C29," ")} -> Aarav | Z29: Sharma
A30: PID0029 | B30: Krishna Sharma | C30: =TRIM(B30) -> Krishna Sharma | D30: =_xlfn.CONCAT(A30,"_",Y30,".pdf") -> PID0029_Krishna.pdf | E30: Male | F30: 31/12/1988 | G30: =DATEVALUE(F30) -> 32508 | H30: =YEAR(G30) -> 1988 | I30: =2026-H30 -> 38 | J30: {=_xlfn.IFS(AND(I30>20,I30<=30),"Young adult",AND(I30>30,I30<=45),"Adult",AND(I30>45,I30<=60),"Senior",AND(I30>60,I30<90),"super senior",TRUE,"Died")} -> Adult | K30: 2 | L30: Uttar Pradesh | M30: West | N30: =VLOOKUP(L30,Facts!$A$2:$B$10,2,FALSE) -> North | Q30: =IF(AND(K30<=5,'Billing Details'!H30>=10000),"High Priority","Regularfollowup") -> Regularfollowup | T30: =IF(AND(Q30="High Priority",'Patient Health Records'!AH30="Yes",'Patient Health Records'!AI30="Critical"), "Need Immediate attention", IF(AND('Patient Health Records'!AI30<>"Critical", 'Patient Health Records'!AH30="Yes"),"Monitor later",IF(AND('Patient Health Records'!AI30="Critical",'Patient Health Records'!AH30="No"),"Ask for readmission","No action"))) -> Monitor later | W30: =_xlfn.XLOOKUP('Patient Demographics'!N30,Facts!$B$2:$B$10,Facts!$A$2:$A$10,FALSE) -> Punjab | X30: =LEFT(C30,FIND(" ",C30)) -> Krishna | Y30: {=_xlfn.TEXTSPLIT(C30," ")} -> Krishna | Z30: Sharma
A31: PID0030 | B31: Aanya Priya Reddy | C31: =TRIM(B31) -> Aanya Priya Reddy | D31: =_xlfn.CONCAT(A31,"_",Y31,".pdf") -> PID0030_Aanya.pdf | E31: Female | F31: 31/12/1998 | G31: =DATEVALUE(F31) -> 36160 | H31: =YEAR(G31) -> 1998 | I31: =2026-H31 -> 28 | J31: {=_xlfn.IFS(AND(I31>20,I31<=30),"Young adult",AND(I31>30,I31<=45),"Adult",AND(I31>45,I31<=60),"Senior",AND(I31>60,I31<90),"super senior",TRUE,"Died")} -> Young adult | K31: 30 | L31: Uttar Pradesh | M31: East | N31: =VLOOKUP(L31,Facts!$A$2:$B$10,2,FALSE) -> North | Q31: =IF(AND(K31<=5,'Billing Details'!H31>=10000),"High Priority","Regularfollowup") -> Regularfollowup | T31: =IF(AND(Q31="High Priority",'Patient Health Records'!AH31="Yes",'Patient Health Records'!AI31="Critical"), "Need Immediate attention", IF(AND('Patient Health Records'!AI31<>"Critical", 'Patient Health Records'!AH31="Yes"),"Monitor later",IF(AND('Patient Health Records'!AI31="Critical",'Patient Health Records'!AH31="No"),"Ask for readmission","No action"))) -> No action | W31: =_xlfn.XLOOKUP('Patient Demographics'!N31,Facts!$B$2:$B$10,Facts!$A$2:$A$10,FALSE) -> Punjab | X31: =LEFT(C31,FIND(" ",C31)) -> Aanya | Y31: {=_xlfn.TEXTSPLIT(C31," ")} -> Aanya | Z31: Priya | AA31: Reddy
A32: PID0031 | B32: Shreya Sharma | C32: =TRIM(B32) -> Shreya Sharma | D32: =_xlfn.CONCAT(A32,"_",Y32,".pdf") -> PID0031_Shreya.pdf | E32: Female | F32: 31/12/1981 | G32: =DATEVALUE(F32) -> 29951 | H32: =YEAR(G32) -> 1981 | I32: =2026-H32 -> 45 | J32: {=_xlfn.IFS(AND(I32>20,I32<=30),"Young adult",AND(I32>30,I32<=45),"Adult",AND(I32>45,I32<=60),"Senior",AND(I32>60,I32<90),"super senior",TRUE,"Died")} -> Adult | K32: 1 | L32: Uttar Pradesh | M32: North | N32: =VLOOKUP(L32,Facts!$A$2:$B$10,2,FALSE) -> North | Q32: =IF(AND(K32<=5,'Billing Details'!H32>=10000),"High Priority","Regularfollowup") -> High Priority | T32: =IF(AND(Q32="High Priority",'Patient Health Records'!AH32="Yes",'Patient Health Records'!AI32="Critical"), "Need Immediate attention", IF(AND('Patient Health Records'!AI32<>"Critical", 'Patient Health Records'!AH32="Yes"),"Monitor later",IF(AND('Patient Health Records'!AI32="Critical",'Patient Health Records'!AH32="No"),"Ask for readmission","No action"))) -> Ask for readmission | W32: =_xlfn.XLOOKUP('Patient Demographics'!N32,Facts!$B$2:$B$10,Facts!$A$2:$A$10,FALSE) -> Punjab | X32: =LEFT(C32,FIND(" ",C32)) -> Shreya | Y32: {=_xlfn.TEXTSPLIT(C32," ")} -> Shreya | Z32: Sharma
A33: PID0032 | B33: Isha Gupta | C33: =TRIM(B33) -> Isha Gupta | D33: =_xlfn.CONCAT(A33,"_",Y33,".pdf") -> PID0032_Isha.pdf | E33: Female | F33: 31/12/1973 | G33: =DATEVALUE(F33) -> 27029 | H33: =YEAR(G33) -> 1973 | I33: =2026-H33 -> 53 | J33: {=_xlfn.IFS(AND(I33>20,I33<=30),"Young adult",AND(I33>30,I33<=45),"Adult",AND(I33>45,I33<=60),"Senior",AND(I33>60,I33<90),"super senior",TRUE,"Died")} -> Senior | K33: 9 | L33: Tamil Nadu | M33: South | N33: =VLOOKUP(L33,Facts!$A$2:$B$10,2,FALSE) -> South | Q33: =IF(AND(K33<=5,'Billing Details'!H33>=10000),"High Priority","Regularfollowup") -> Regularfollowup | T33: =IF(AND(Q33="High Priority",'Patient Health Records'!AH33="Yes",'Patient Health Records'!AI33="Critical"), "Need Immediate attention", IF(AND('Patient Health Records'!AI33<>"Critical", 'Patient Health Records'!AH33="Yes"),"Monitor later",IF(AND('Patient Health Records'!AI33="Critical",'Patient Health Records'!AH33="No"),"Ask for readmission","No action"))) -> No action | W33: =_xlfn.XLOOKUP('Patient Demographics'!N33,Facts!$B$2:$B$10,Facts!$A$2:$A$10,FALSE) -> Tamil Nadu | X33: =LEFT(C33,FIND(" ",C33)) -> Isha | Y33: {=_xlfn.TEXTSPLIT(C33," ")} -> Isha | Z33: Gupta
A34: PID0033 | B34: Diya Sharma | C34: =TRIM(B34) -> Diya Sharma | D34: =_xlfn.CONCAT(A34,"_",Y34,".pdf") -> PID0033_Diya.pdf | E34: Female | F34: 31/12/1998 | G34: =DATEVALUE(F34) -> 36160 | H34: =YEAR(G34) -> 1998 | I34: =2026-H34 -> 28 | J34: {=_xlfn.IFS(AND(I34>20,I34<=30),"Young adult",AND(I34>30,I34<=45),"Adult",AND(I34>45,I34<=60),"Senior",AND(I34>60,I34<90),"super senior",TRUE,"Died")} -> Young adult | K34: 15 | L34: Maharashtra | M34: West | N34: =VLOOKUP(L34,Facts!$A$2:$B$10,2,FALSE) -> West | Q34: =IF(AND(K34<=5,'Billing Details'!H34>=10000),"High Priority","Regularfollowup") -> Regularfollowup | T34: =IF(AND(Q34="High Priority",'Patient Health Records'!AH34="Yes",'Patient Health Records'!AI34="Critical"), "Need Immediate attention", IF(AND('Patient Health Records'!AI34<>"Critical", 'Patient Health Records'!AH34="Yes"),"Monitor later",IF(AND('Patient Health Records'!AI34="Critical",'Patient Health Records'!AH34="No"),"Ask for readmission","No action"))) -> Monitor later | W34: =_xlfn.XLOOKUP('Patient Demographics'!N34,Facts!$B$2:$B$10,Facts!$A$2:$A$10,FALSE) -> Maharashtra | X34: =LEFT(C34,FIND(" ",C34)) -> Diya | Y34: {=_xlfn.TEXTSPLIT(C34," ")} -> Diya | Z34: Sharma
A35: PID0034 | B35: Aditya Mehta | C35: =TRIM(B35) -> Aditya Mehta | D35: =_xlfn.CONCAT(A35,"_",Y35,".pdf") -> PID0034_Aditya.pdf | E35: Male | F35: 01/01/1984 | G35: =DATEVALUE(F35) -> 30682 | H35: =YEAR(G35) -> 1984 | I35: =2026-H35 -> 42 | J35: {=_xlfn.IFS(AND(I35>20,I35<=30),"Young adult",AND(I35>30,I35<=45),"Adult",AND(I35>45,I35<=60),"Senior",AND(I35>60,I35<90),"super senior",TRUE,"Died")} -> Adult | K35: 15 | L35: Punjab | M35: South | N35: =VLOOKUP(L35,Facts!$A$2:$B$10,2,FALSE) -> North | Q35: =IF(AND(K35<=5,'Billing Details'!H35>=10000),"High Priority","Regularfollowup") -> Regularfollowup | T35: =IF(AND(Q35="High Priority",'Patient Health Records'!AH35="Yes",'Patient Health Records'!AI35="Critical"), "Need Immediate attention", IF(AND('Patient Health Records'!AI35<>"Critical", 'Patient Health Records'!AH35="Yes"),"Monitor later",IF(AND('Patient Health Records'!AI35="Critical",'Patient Health Records'!AH35="No"),"Ask for readmission","No action"))) -> No action | W35: =_xlfn.XLOOKUP('Patient Demographics'!N35,Facts!$B$2:$B$10,Facts!$A$2:$A$10,FALSE) -> Punjab | X35: =LEFT(C35,FIND(" ",C35)) -> Aditya | Y35: {=_xlfn.TEXTSPLIT(C35," ")} -> Aditya | Z35: Mehta
A36: PID0035 | B36: Krishna Sharma | C36: =TRIM(B36) -> Krishna Sharma | D36: =_xlfn.CONCAT(A36,"_",Y36,".pdf") -> PID0035_Krishna.pdf | E36: Male | F36: 01/01/1976 | G36: =DATEVALUE(F36) -> 27760 | H36: =YEAR(G36) -> 1976 | I36: =2026-H36 -> 50 | J36: {=_xlfn.IFS(AND(I36>20,I36<=30),"Young adult",AND(I36>30,I36<=45),"Adult",AND(I36>45,I36<=60),"Senior",AND(I36>60,I36<90),"super senior",TRUE,"Died")} -> Senior | K36: 2 | L36: Uttar Pradesh | M36: East | N36: =VLOOKUP(L36,Facts!$A$2:$B$10,2,FALSE) -> North | Q36: =IF(AND(K36<=5,'Billing Details'!H36>=10000),"High Priority","Regularfollowup") -> Regularfollowup | T36: =IF(AND(Q36="High Priority",'Patient Health Records'!AH36="Yes",'Patient Health Records'!AI36="Critical"), "Need Immediate attention", IF(AND('Patient Health Records'!AI36<>"Critical", 'Patient Health Records'!AH36="Yes"),"Monitor later",IF(AND('Patient Health Records'!AI36="Critical",'Patient Health Records'!AH36="No"),"Ask for readmission","No action"))) -> No action | W36: =_xlfn.XLOOKUP('Patient Demographics'!N36,Facts!$B$2:$B$10,Facts!$A$2:$A$10,FALSE) -> Punjab | X36: =LEFT(C36,FIND(" ",C36)) -> Krishna | Y36: {=_xlfn.TEXTSPLIT(C36," ")} -> Krishna | Z36: Sharma
A37: PID0036 | B37: Riya Gupta | C37: =TRIM(B37) -> Riya Gupta | D37: =_xlfn.CONCAT(A37,"_",Y37,".pdf") -> PID0036_Riya.pdf | E37: Female | F37: 31/12/1968 | G37: =DATEVALUE(F37) -> 25203 | H37: =YEAR(G37) -> 1968 | I37: =2026-H37 -> 58 | J37: {=_xlfn.IFS(AND(I37>20,I37<=30),"Young adult",AND(I37>30,I37<=45),"Adult",AND(I37>45,I37<=60),"Senior",AND(I37>60,I37<90),"super senior",TRUE,"Died")} -> Senior | K37: 4 | L37: Punjab | M37: North | N37: =VLOOKUP(L37,Facts!$A$2:$B$10,2,FALSE) -> North | Q37: =IF(AND(K37<=5,'Billing Details'!H37>=10000),"High Priority","Regularfollowup") -> Regularfollowup | T37: =IF(AND(Q37="High Priority",'Patient Health Records'!AH37="Yes",'Patient Health Records'!AI37="Critical"), "Need Immediate attention", IF(AND('Patient Health Records'!AI37<>"Critical", 'Patient Health Records'!AH37="Yes"),"Monitor later",IF(AND('Patient Health Records'!AI37="Critical",'Patient Health Records'!AH37="No"),"Ask for readmission","No action"))) -> No action | W37: =_xlfn.XLOOKUP('Patient Demographics'!N37,Facts!$B$2:$B$10,Facts!$A$2:$A$10,FALSE) -> Punjab | X37: =LEFT(C37,FIND(" ",C37)) -> Riya | Y37: {=_xlfn.TEXTSPLIT(C37," ")} -> Riya | Z37: Gupta
A38: PID0037 | B38: Aanya Priya Sharma | C38: =TRIM(B38) -> Aanya Priya Sharma | D38: =_xlfn.CONCAT(A38,"_",Y38,".pdf") -> PID0037_Aanya.pdf | E38: Female | F38: 01/01/1964 | G38: =DATEVALUE(F38) -> 23377 | H38: =YEAR(G38) -> 1964 | I38: =2026-H38 -> 62 | J38: {=_xlfn.IFS(AND(I38>20,I38<=30),"Young adult",AND(I38>30,I38<=45),"Adult",AND(I38>45,I38<=60),"Senior",AND(I38>60,I38<90),"super senior",TRUE,"Died")} -> super senior | K38: 5 | L38: Gujarat | M38: South | N38: =VLOOKUP(L38,Facts!$A$2:$B$10,2,FALSE) -> West | Q38: =IF(AND(K38<=5,'Billing Details'!H38>=10000),"High Priority","Regularfollowup") -> High Priority | T38: =IF(AND(Q38="High Priority",'Patient Health Records'!AH38="Yes",'Patient Health Records'!AI38="Critical"), "Need Immediate attention", IF(AND('Patient Health Records'!AI38<>"Critical", 'Patient Health Records'!AH38="Yes"),"Monitor later",IF(AND('Patient Health Records'!AI38="Critical",'Patient Health Records'!AH38="No"),"Ask for readmission","No action"))) -> No action | W38: =_xlfn.XLOOKUP('Patient Demographics'!N38,Facts!$B$2:$B$10,Facts!$A$2:$A$10,FALSE) -> Maharashtra | X38: =LEFT(C38,FIND(" ",C38)) -> Aanya | Y38: {=_xlfn.TEXTSPLIT(C38," ")} -> Aanya | Z38: Priya | AA38: Sharma
A39: PID0038 | B39: Sai Priya Mehta | C39: =TRIM(B39) -> Sai Priya Mehta | D39: =_xlfn.CONCAT(A39,"_",Y39,".pdf") -> PID0038_Sai.pdf | E39: Male | F39: 31-12-1988 | G39: =DATEVALUE(F39) -> 32508 | H39: =YEAR(G39) -> 1988 | I39: =2026-H39 -> 38 | J39: {=_xlfn.IFS(AND(I39>20,I39<=30),"Young adult",AND(I39>30,I39<=45),"Adult",AND(I39>45,I39<=60),"Senior",AND(I39>60,I39<90),"super senior",TRUE,"Died")} -> Adult | K39: 15 | L39: Karnataka | M39: South | N39: =VLOOKUP(L39,Facts!$A$2:$B$10,2,FALSE) -> South | Q39: =IF(AND(K39<=5,'Billing Details'!H39>=10000),"High Priority","Regularfollowup") -> Regularfollowup | T39: =IF(AND(Q39="High Priority",'Patient Health Records'!AH39="Yes",'Patient Health Records'!AI39="Critical"), "Need Immediate attention", IF(AND('Patient Health Records'!AI39<>"Critical", 'Patient Health Records'!AH39="Yes"),"Monitor later",IF(AND('Patient Health Records'!AI39="Critical",'Patient Health Records'!AH39="No"),"Ask for readmission","No action"))) -> No action | W39: =_xlfn.XLOOKUP('Patient Demographics'!N39,Facts!$B$2:$B$10,Facts!$A$2:$A$10,FALSE) -> Tamil Nadu | X39: =LEFT(C39,FIND(" ",C39)) -> Sai | Y39: {=_xlfn.TEXTSPLIT(C39," ")} -> Sai | Z39: Priya | AA39: Mehta
A40: PID0039 | B40: Isha Kumar Sharma | C40: =TRIM(B40) -> Isha Kumar Sharma | D40: =_xlfn.CONCAT(A40,"_",Y40,".pdf") -> PID0039_Isha.pdf | E40: Female | F40: 31/12/1973 | G40: =DATEVALUE(F40) -> 27029 | H40: =YEAR(G40) -> 1973 | I40: =2026-H40 -> 53 | J40: {=_xlfn.IFS(AND(I40>20,I40<=30),"Young adult",AND(I40>30,I40<=45),"Adult",AND(I40>45,I40<=60),"Senior",AND(I40>60,I40<90),"super senior",TRUE,"Died")} -> Senior | K40: 25 | L40: Gujarat | M40: West | N40: =VLOOKUP(L40,Facts!$A$2:$B$10,2,FALSE) -> West | Q40: =IF(AND(K40<=5,'Billing Details'!H40>=10000),"High Priority","Regularfollowup") -> Regularfollowup | T40: =IF(AND(Q40="High Priority",'Patient Health Records'!AH40="Yes",'Patient Health Records'!AI40="Critical"), "Need Immediate attention", IF(AND('Patient Health Records'!AI40<>"Critical", 'Patient Health Records'!AH40="Yes"),"Monitor later",IF(AND('Patient Health Records'!AI40="Critical",'Patient Health Records'!AH40="No"),"Ask for readmission","No action"))) -> No action | W40: =_xlfn.XLOOKUP('Patient Demographics'!N40,Facts!$B$2:$B$10,Facts!$A$2:$A$10,FALSE) -> Maharashtra | X40: =LEFT(C40,FIND(" ",C40)) -> Isha | Y40: {=_xlfn.TEXTSPLIT(C40," ")} -> Isha | Z40: Kumar | AA40: Sharma
...

Sheet Patient Health Records
A1: Patient Id | B1: Blood Type | C1: Height (cm) | D1: Height(mtr) | E1: Updated Weight(kgs) | F1: BMI | G1: Weight (kg) | H1: Fever | I1: first clean | J1: Final Fever | K1: Cough | L1: First clean | M1: Final Cough | N1: Fatigue | O1: first clean | P1: Final Fatigue | Q1: Difficulty Breathing | R1: First clean | S1: Final Difficulty Breathing | T1: Blood Pressure | U1: Cholesterol Level | V1: Smoking Status | W1: first clean | X1: final Smoking Status | Y1: Drinking Status | Z1: first clean | AA1: Final Drinking status | AB1: Diabetes | AC1: first clean | AD1: Diabetes(DM) | AE1: Condition | AF1: Updated_Condition | AG1: Readmission | AH1: Final Readmission | AI1: Outcome | AJ1: Satisfaction | AK1: Unique Satisfaction | AL1: Total count/Satisfcation
A2: PID0001 | B2: O+ | C2: 168 | D2: =C2/100 -> 1.68 | E2: =ROUND(G2,1) -> 82.4 | F2: =E2/D2^2 -> 29.195011 | G2: 82.4 | H2: FALSE | I2: =IF(ISBLANK(H2),FALSE,H2) -> FALSE | J2: =IF(I2="YES",TRUE,IF(I2="No",FALSE,I2)) -> FALSE | K2: FALSE | L2: =IF(ISBLANK(K2),FALSE,K2) -> FALSE | M2: =IF(L2="Yes",TRUE,IF(L2="No",FALSE,L2)) -> FALSE | N2: FALSE | O2: =IF(ISBLANK(N2),"FALSE",N2) -> FALSE | P2: =IF(O2="yes",TRUE,IF(O2="No",FALSE,O2)) -> FALSE | Q2: FALSE | R2: =IF(ISBLANK(Q2),FALSE,Q2) -> FALSE | S2: =IF(R2="Yes",TRUE,IF(R2="No",FALSE,R2)) -> FALSE | T2: 129/83 | U2: 151 | V2: FALSE | W2: =IF(ISBLANK(V2),FALSE,V2) -> FALSE | X2: =IF(W2="Yes",TRUE,IF(W2="No",FALSE,FALSE)) -> FALSE | Y2: TRUE | Z2: =IF(ISBLANK(Y2),FALSE,Y2) -> TRUE | AA2: =IF(Z2="YES",TRUE,IF(Z2="No",FALSE,Z2)) -> TRUE | AB2: TRUE | AC2: =IF(ISBLANK(AB2),"FALSE",AB2) -> TRUE | AD2: =IF(AC2="Yes",TRUE,IF(AC2="No",FALSE,AC2)) -> TRUE | AE2: Fractured Leg | AF2: =PROPER(AE2) -> Fractured Leg | AG2: No | AH2: =IF(ISBLANK(AG2),"No",AG2) -> No | AI2: Critical | AJ2: Dissatisfied | AK2: {=_xlfn.UNIQUE(AJ2:AJ1001)} -> Dissatisfied | AL2: =COUNTIF(AJ2:AJ1001,AK2) -> 200
A3: PID0002 | B3: AB- | C3: 152 | D3: =C3/100 -> 1.52 | E3: =ROUND(G3,1) -> 64.8 | F3: =E3/D3^2 -> 28.047091 | G3: 64.8 | H3: FALSE | I3: =IF(ISBLANK(H3),FALSE,H3) -> FALSE | J3: =IF(I3="YES",TRUE,IF(I3="No",FALSE,I3)) -> FALSE | K3: FALSE | L3: =IF(ISBLANK(K3),FALSE,K3) -> FALSE | M3: =IF(L3="Yes",TRUE,IF(L3="No",FALSE,L3)) -> FALSE | N3: FALSE | O3: =IF(ISBLANK(N3),"FALSE",N3) -> FALSE | P3: =IF(O3="yes",TRUE,IF(O3="No",FALSE,O3)) -> FALSE | Q3: FALSE | R3: =IF(ISBLANK(Q3),FALSE,Q3) -> FALSE | S3: =IF(R3="Yes",TRUE,IF(R3="No",FALSE,R3)) -> FALSE | T3: 112/81 | U3: 191 | V3: FALSE | W3: =IF(ISBLANK(V3),FALSE,V3) -> FALSE | X3: =IF(W3="Yes",TRUE,IF(W3="No",FALSE,FALSE)) -> FALSE | Y3: TRUE | Z3: =IF(ISBLANK(Y3),FALSE,Y3) -> TRUE | AA3: =IF(Z3="YES",TRUE,IF(Z3="No",FALSE,Z3)) -> TRUE | AB3: TRUE | AC3: =IF(ISBLANK(AB3),"FALSE",AB3) -> TRUE | AD3: =IF(AC3="Yes",TRUE,IF(AC3="No",FALSE,AC3)) -> TRUE | AE3: prostate cancer | AF3: =PROPER(AE3) -> Prostate Cancer | AG3: No | AH3: =IF(ISBLANK(AG3),"No",AG3) -> No | AI3: Recovered | AJ3: Very Dissatisfied | AK3: Very Dissatisfied | AL3: =COUNTIF(AJ3:AJ1002,AK3) -> 190
A4: PID0003 | B4: B+ | C4: 170 | D4: =C4/100 -> 1.7 | E4: =ROUND(G4,1) -> 69.4 | F4: =E4/D4^2 -> 24.013841 | G4: 69.42323 | H4: TRUE | I4: =IF(ISBLANK(H4),FALSE,H4) -> TRUE | J4: =IF(I4="YES",TRUE,IF(I4="No",FALSE,I4)) -> TRUE | K4: FALSE | L4: =IF(ISBLANK(K4),FALSE,K4) -> FALSE | M4: =IF(L4="Yes",TRUE,IF(L4="No",FALSE,L4)) -> FALSE | N4: FALSE | O4: =IF(ISBLANK(N4),"FALSE",N4) -> FALSE | P4: =IF(O4="yes",TRUE,IF(O4="No",FALSE,O4)) -> FALSE | Q4: FALSE | R4: =IF(ISBLANK(Q4),FALSE,Q4) -> FALSE | S4: =IF(R4="Yes",TRUE,IF(R4="No",FALSE,R4)) -> FALSE | T4: 125/74 | U4: 152 | V4: FALSE | W4: =IF(ISBLANK(V4),FALSE,V4) -> FALSE | X4: =IF(W4="Yes",TRUE,IF(W4="No",FALSE,FALSE)) -> FALSE | Z4: =IF(ISBLANK(Y4),FALSE,Y4) -> FALSE | AA4: =IF(Z4="YES",TRUE,IF(Z4="No",FALSE,Z4)) -> FALSE | AB4: FALSE | AC4: =IF(ISBLANK(AB4),"FALSE",AB4) -> FALSE | AD4: =IF(AC4="Yes",TRUE,IF(AC4="No",FALSE,AC4)) -> FALSE | AE4: Stroke | AF4: =PROPER(AE4) -> Stroke | AG4: No | AH4: =IF(ISBLANK(AG4),"No",AG4) -> No | AI4: Critical | AJ4: Very Satisfied | AK4: Very Satisfied | AL4: =COUNTIF(AJ4:AJ1003,AK4) -> 206
A5: PID0004 | B5: A- | C5: 169 | D5: =C5/100 -> 1.69 | E5: =ROUND(G5,1) -> 89.3 | F5: =E5/D5^2 -> 31.266412 | G5: 89.3 | H5: TRUE | I5: =IF(ISBLANK(H5),FALSE,H5) -> TRUE | J5: =IF(I5="YES",TRUE,IF(I5="No",FALSE,I5)) -> TRUE | K5: TRUE | L5: =IF(ISBLANK(K5),FALSE,K5) -> TRUE | M5: =IF(L5="Yes",TRUE,IF(L5="No",FALSE,L5)) -> TRUE | N5: FALSE | O5: =IF(ISBLANK(N5),"FALSE",N5) -> FALSE | P5: =IF(O5="yes",TRUE,IF(O5="No",FALSE,O5)) -> FALSE | Q5: FALSE | R5: =IF(ISBLANK(Q5),FALSE,Q5) -> FALSE | S5: =IF(R5="Yes",TRUE,IF(R5="No",FALSE,R5)) -> FALSE | T5: 122/72 | U5: 203 | V5: TRUE | W5: =IF(ISBLANK(V5),FALSE,V5) -> TRUE | X5: =IF(W5="Yes",TRUE,IF(W5="No",FALSE,FALSE)) -> FALSE | Y5: FALSE | Z5: =IF(ISBLANK(Y5),FALSE,Y5) -> FALSE | AA5: =IF(Z5="YES",TRUE,IF(Z5="No",FALSE,Z5)) -> FALSE | AB5: TRUE | AC5: =IF(ISBLANK(AB5),"FALSE",AB5) -> TRUE | AD5: =IF(AC5="Yes",TRUE,IF(AC5="No",FALSE,AC5)) -> TRUE | AE5: Heart Attack | AF5: =PROPER(AE5) -> Heart Attack | AG5: No | AH5: =IF(ISBLANK(AG5),"No",AG5) -> No | AI5: Critical | AJ5: Neutral | AK5: Neutral | AL5: =COUNTIF(AJ5:AJ1004,AK5) -> 212
